<?xml version="1.0" ?>
<!-- This URDF was automatically created by SolidWorks to URDF Exporter! Originally created by Stephen Brawner (brawner@gmail.com) 
     Commit Version: 1.6.0-4-g7f85cfe  Build Version: 1.6.7995.38578
     For more information, please see http://wiki.ros.org/sw_urdf_exporter -->

<robot 
  name="robot_name" xmlns:xacro="http://ros.org/wiki/xacro">

  <xacro:macro name="body_color">
    <visual>
    <material>
        <ambient>0.15294 0.16078 0.96078 1</ambient>
        <diffuse>0.15294 0.16078 0.96078 1</diffuse>
        <specular>0.1 0.1 0.1 1</specular>
        <emissive>0 0 0 0</emissive>
    </material>
    </visual>
  </xacro:macro>

  <xacro:macro name="axle_color">
    <visual>
    <material>
        <ambient>0.79216 0.81961 0.93333 1</ambient>
        <diffuse>0.79216 0.81961 0.93333 1</diffuse>
        <specular>0.1 0.1 0.1 1</specular>
        <emissive>0 0 0 0</emissive>
    </material>
    </visual>
  </xacro:macro>

  <xacro:macro name="wheel_color">
    <visual>
    <material>
        <ambient>0.0 0.0 0.0 1</ambient>
        <diffuse>0.0 0.0 0.0 1</diffuse>
        <specular>0.1 0.1 0.1 1</specular>
        <emissive>0 0 0 0</emissive>
    </material>
    </visual>
  </xacro:macro>

  <link name="dummy_link"></link>
  <link
    name="base_link">
    <inertial>
      <origin
        xyz="-0.12098 -0.036587 -0.041693"
        rpy="0 0 0" />
      <mass
        value="3" />
      <inertia
        ixx="2.9365"
        ixy="0.38432"
        ixz="-0.00028685"
        iyy="10.018"
        iyz="0.00021954"
        izz="8.251" />
    </inertial>
    <visual>
      <origin
        xyz="0 0 0"
        rpy="0 0 0" />
      <geometry>
        <mesh
          filename="package://car/meshes/base_link.STL" />
      </geometry>
      <material
        name="">
        <color
          rgba="0.79216 0.81961 0.93333 1" />
      </material>
    </visual>
    <collision>
      <origin
        xyz="0 0 0"
        rpy="0 0 0" />
      <geometry>
        <mesh
          filename="package://car/meshes/base_link.STL" />
      </geometry>
    </collision>
  </link>
  <joint name="dummy_joint" type="fixed">
    <origin rpy="0 0 0" xyz="0 0 0" />
    <parent link="dummy_link"/>
    <child link="base_link"/>
  </joint>
  <link
    name="br_axle_link">
    <inertial>
      <origin
        xyz="0.01325 -4.996E-16 0.1753"
        rpy="0 0 0" />
      <mass
        value="0.77981" />
      <inertia
        ixx="0.0064774"
        ixy="2.2484E-17"
        ixz="-0.00095429"
        iyy="0.007066"
        iyz="3.7929E-17"
        izz="0.00085445" />
    </inertial>
    <visual>
      <origin
        xyz="0 0 0"
        rpy="0 0 0" />
      <geometry>
        <mesh
          filename="package://car/meshes/br_axle_link.STL" />
      </geometry>
      <material
        name="">
        <color
          rgba="0.79216 0.81961 0.93333 1" />
      </material>
    </visual>
    <collision>
      <origin
        xyz="0 0 0"
        rpy="0 0 0" />
      <geometry>
        <mesh
          filename="package://car/meshes/br_axle_link.STL" />
      </geometry>
    </collision>
  </link>
  <joint
    name="br_axle_joint"
    type="fixed">
    <origin
      xyz="-0.43846 -0.059938 -0.0042092"
      rpy="-3.1416 0 -1.5741" />
    <parent
      link="base_link" />
    <child
      link="br_axle_link" />
    <axis
      xyz="0 0 0" />
  </joint>
  <link
    name="br_wheel_link">
    <inertial>
      <origin
        xyz="0 -1.0408E-17 -0.039115"
        rpy="0 0 0" />
      <mass
        value="1.287" />
      <inertia
        ixx="0.0026336"
        ixy="3.8239E-19"
        ixz="1.9016E-19"
        iyy="0.0026336"
        iyz="1.0651E-18"
        izz="0.0040023" />
    </inertial>
    <visual>
      <origin
        xyz="0 0 0"
        rpy="0 0 0" />
      <geometry>
        <mesh
          filename="package://car/meshes/br_wheel_link.STL" />
      </geometry>
      <material
        name="">
        <color
          rgba="0.79608 0.82353 0.93725 1" />
      </material>
    </visual>
    <collision>
      <origin
        xyz="0 0 0"
        rpy="0 0 0" />
      <geometry>
        <mesh
          filename="package://car/meshes/br_wheel_link.STL" />
      </geometry>
    </collision>
  </link>
  <joint
    name="br_wheel_joint"
    type="continuous">
    <origin
      xyz="0.053315 0 0.26765"
      rpy="1.5708 0.61104 -1.5708" />
    <parent
      link="br_axle_link" />
    <child
      link="br_wheel_link" />
    <axis
      xyz="0 0 1" />
    <limit
      effort="100"
      velocity="1000" />
  </joint>
  <link
    name="bl_axle_link">
    <inertial>
      <origin
        xyz="0.01325 2.387E-15 0.1753"
        rpy="0 0 0" />
      <mass
        value="0.77981" />
      <inertia
        ixx="0.0064774"
        ixy="-1.0652E-16"
        ixz="-0.00095429"
        iyy="0.007066"
        iyz="-1.7503E-16"
        izz="0.00085445" />
    </inertial>
    <visual>
      <origin
        xyz="0 0 0"
        rpy="0 0 0" />
      <geometry>
        <mesh
          filename="package://car/meshes/bl_axle_link.STL" />
      </geometry>
      <material
        name="">
        <color
          rgba="0.79216 0.81961 0.93333 1" />
      </material>
    </visual>
    <collision>
      <origin
        xyz="0 0 0"
        rpy="0 0 0" />
      <geometry>
        <mesh
          filename="package://car/meshes/bl_axle_link.STL" />
      </geometry>
    </collision>
  </link>
  <joint
    name="bl_axle_joint"
    type="fixed">
    <origin
      xyz="-0.43846 0.14326 -0.0042092"
      rpy="3.1416 0 1.5702" />
    <parent
      link="base_link" />
    <child
      link="bl_axle_link" />
    <axis
      xyz="0 0 0" />
  </joint>
  <link
    name="bl_wheel_link">
    <inertial>
      <origin
        xyz="0 0 -0.039116"
        rpy="0 0 0" />
      <mass
        value="1.287" />
      <inertia
        ixx="0.0026336"
        ixy="-2.0149E-19"
        ixz="-3.5639E-19"
        iyy="0.0026336"
        iyz="1.1603E-18"
        izz="0.0040023" />
    </inertial>
    <visual>
      <origin
        xyz="0 0 0"
        rpy="0 0 0" />
      <geometry>
        <mesh
          filename="package://car/meshes/bl_wheel_link.STL" />
      </geometry>
      <material
        name="">
        <color
          rgba="0.79608 0.82353 0.93725 1" />
      </material>
    </visual>
    <collision>
      <origin
        xyz="0 0 0"
        rpy="0 0 0" />
      <geometry>
        <mesh
          filename="package://car/meshes/bl_wheel_link.STL" />
      </geometry>
    </collision>
  </link>
  <joint
    name="bl_wheel_joint"
    type="continuous">
    <origin
      xyz="0.053314 0 0.26765"
      rpy="-1.5708 -0.29845 1.5708" />
    <parent
      link="bl_axle_link" />
    <child
      link="bl_wheel_link" />
    <axis
      xyz="0 0 1" />
    <limit
      effort="100"
      velocity="1000" />
  </joint>
  <link
    name="fl_axle_link">
    <inertial>
      <origin
        xyz="0.01325 -7.7716E-16 0.1753"
        rpy="0 0 0" />
      <mass
        value="0.77981" />
      <inertia
        ixx="0.0064774"
        ixy="3.4515E-17"
        ixz="-0.00095429"
        iyy="0.007066"
        iyz="5.6776E-17"
        izz="0.00085445" />
    </inertial>
    <visual>
      <origin
        xyz="0 0 0"
        rpy="0 0 0" />
      <geometry>
        <mesh
          filename="package://car/meshes/fl_axle_link.STL" />
      </geometry>
      <material
        name="">
        <color
          rgba="0.79216 0.81961 0.93333 1" />
      </material>
    </visual>
    <collision>
      <origin
        xyz="0 0 0"
        rpy="0 0 0" />
      <geometry>
        <mesh
          filename="package://car/meshes/fl_axle_link.STL" />
      </geometry>
    </collision>
  </link>
  <joint
    name="fl_axle_joint"
    type="revolute">
    <origin
      xyz="0.27274 0.14326 -0.0042092"
      rpy="3.1416 0 1.5755" />
    <parent
      link="base_link" />
    <child
      link="fl_axle_link" />
    <axis
      xyz="0 0 1" />
    <limit
      lower="-3.14"
      upper="3.14"
      effort="100"
      velocity="1000" />
  </joint>
  <link
    name="fl_wheel_link">
    <inertial>
      <origin
        xyz="-3.8858E-16 0 -0.039855"
        rpy="0 0 0" />
      <mass
        value="1.287" />
      <inertia
        ixx="0.0026336"
        ixy="-1.6262E-20"
        ixz="-9.0802E-19"
        iyy="0.0026336"
        iyz="-1.9713E-18"
        izz="0.0040023" />
    </inertial>
    <visual>
      <origin
        xyz="0 0 0"
        rpy="0 0 0" />
      <geometry>
        <mesh
          filename="package://car/meshes/fl_wheel_link.STL" />
      </geometry>
      <material
        name="">
        <color
          rgba="0.79608 0.82353 0.93725 1" />
      </material>
    </visual>
    <collision>
      <origin
        xyz="0 0 0"
        rpy="0 0 0" />
      <geometry>
        <mesh
          filename="package://car/meshes/fl_wheel_link.STL" />
      </geometry>
    </collision>
  </link>
  <joint
    name="fl_wheel_joint"
    type="continuous">
    <origin
      xyz="0.052575 0 0.26765"
      rpy="-1.5708 0.038943 1.5708" />
    <parent
      link="fl_axle_link" />
    <child
      link="fl_wheel_link" />
    <axis
      xyz="0 0 1" />
    <limit
      effort="100"
      velocity="1000" />
  </joint>
  <link
    name="fr_axle_link">
    <inertial>
      <origin
        xyz="0.01325 2.2204E-16 0.1753"
        rpy="0 0 0" />
      <mass
        value="0.77981" />
      <inertia
        ixx="0.0064774"
        ixy="-6.8101E-18"
        ixz="-0.00095429"
        iyy="0.007066"
        iyz="-1.2415E-17"
        izz="0.00085445" />
    </inertial>
    <visual>
      <origin
        xyz="0 0 0"
        rpy="0 0 0" />
      <geometry>
        <mesh
          filename="package://car/meshes/fr_axle_link.STL" />
      </geometry>
      <material
        name="">
        <color
          rgba="0.79216 0.81961 0.93333 1" />
      </material>
    </visual>
    <collision>
      <origin
        xyz="0 0 0"
        rpy="0 0 0" />
      <geometry>
        <mesh
          filename="package://car/meshes/fr_axle_link.STL" />
      </geometry>
    </collision>
  </link>
  <joint
    name="fr_axle_joint"
    type="revolute">
    <origin
      xyz="0.27274 -0.059938 -0.0042092"
      rpy="-3.1416 0 -1.5733" />
    <parent
      link="base_link" />
    <child
      link="fr_axle_link" />
    <axis
      xyz="0 0 1" />
    <limit
      lower="-3.14"
      upper="3.14"
      effort="100"
      velocity="1000" />
  </joint>
  <link
    name="fr_wheel_link">
    <inertial>
      <origin
        xyz="7.7716E-16 2.2204E-16 -0.039116"
        rpy="0 0 0" />
      <mass
        value="1.287" />
      <inertia
        ixx="0.0026336"
        ixy="-2.7991E-19"
        ixz="2.6766E-19"
        iyy="0.0026336"
        iyz="-5.5798E-19"
        izz="0.0040023" />
    </inertial>
    <visual>
      <origin
        xyz="0 0 0"
        rpy="0 0 0" />
      <geometry>
        <mesh
          filename="package://car/meshes/fr_wheel_link.STL" />
      </geometry>
      <material
        name="">
        <color
          rgba="0.79608 0.82353 0.93725 1" />
      </material>
    </visual>
    <collision>
      <origin
        xyz="0 0 0"
        rpy="0 0 0" />
      <geometry>
        <mesh
          filename="package://car/meshes/fr_wheel_link.STL" />
      </geometry>
    </collision>
  </link>
  <joint
    name="fr_wheel_joint"
    type="continuous">
    <origin
      xyz="0.053314 0 0.26765"
      rpy="1.5708 -0.41357 -1.5708" />
    <parent
      link="fr_axle_link" />
    <child
      link="fr_wheel_link" />
    <axis
      xyz="0 0 1" />
    <limit
      effort="100"
      velocity="1000" />
  </joint>
  <link name = "laser_frame">
    <visual>
      <geometry>
        <cylinder radius="0.05" length="0.04"/>
      </geometry>
      <material name="red">
        <color rgba="0 0 0.8 1"/>
      </material>
    </visual>
    <collision>
      <geometry>
        <cylinder radius="0.05" length="0.04"/>
      </geometry>
    </collision>
  </link>
  <joint name="laser_joint" type="fixed">
    <parent link="base_link"/>
    <child link="laser_frame"/>
    <origin xyz="-0.1 0.03 0.19" rpy="0 0 0"/>
  </joint>

  <ros2_control name="GazeboSystem" type="system">
    <hardware>
        <plugin>gazebo_ros2_control/GazeboSystem</plugin>
    </hardware>
  # Velocity Controllers

  <joint name="br_wheel_joint">
      <command_interface name="velocity">
          <param name="min">-1000.0</param>
          <param name="max">1000.0</param>
      </command_interface>
      <state_interface name="position"/>
      <state_interface name="velocity"/>
  </joint>

  <joint name="bl_wheel_joint">
      <command_interface name="velocity">
          <param name="min">-1000.0</param>
          <param name="max">1000.0</param>
      </command_interface>
      <state_interface name="position"/>
      <state_interface name="velocity"/>
  </joint>

  <joint name="fl_wheel_joint">
      <command_interface name="velocity">
          <param name="min">-1000.0</param>
          <param name="max">1000.0</param>
      </command_interface>
      <state_interface name="position"/>
      <state_interface name="velocity"/>
  </joint>

  <joint name="fr_wheel_joint">
      <command_interface name="velocity">
          <param name="min">-1000.0</param>
          <param name="max">1000.0</param>
      </command_interface>
      <state_interface name="position"/>
      <state_interface name="velocity"/>
  </joint>

  # Position Controller
  <joint name="fl_axle_joint">
      <command_interface name="position">
          <param name="min">-3.14</param>
          <param name="max">3.14</param>
      </command_interface>
      <state_interface name="position"/>
      <state_interface name="velocity"/>
  </joint>

  <joint name="fr_axle_joint">
      <command_interface name="position">
          <param name="min">-3.14</param>
          <param name="max">3.14</param>
      </command_interface>
      <state_interface name="position"/>
      <state_interface name="velocity"/>
  </joint>

  </ros2_control>

  <gazebo>
    <plugin filename="libgazebo_ros2_control.so" name="gazebo_ros2_control">
        <parameters>$(find car)/config/control.yaml</parameters>
    </plugin>
  </gazebo>

  <gazebo reference="base_link">
    <xacro:body_color />
  </gazebo>

  <gazebo reference="fr_axle_link">
      <xacro:axle_color />
  </gazebo>

  <gazebo reference="br_axle_link">
      <xacro:axle_color />
  </gazebo>

  <gazebo reference="fl_axle_link">
      <xacro:axle_color />
  </gazebo>

  <gazebo reference="bl_axle_link">
      <xacro:axle_color />
  </gazebo>

  <gazebo reference="fr_wheel_link">
      <xacro:wheel_color />
  </gazebo>

  <gazebo reference="br_wheel_link">
      <xacro:wheel_color />
  </gazebo>

  <gazebo reference="fl_wheel_link">
      <xacro:wheel_color />
  </gazebo>

  <gazebo reference="bl_wheel_link">
      <xacro:wheel_color />
  </gazebo>

  <gazebo reference="laser_frame">
    <material>Gazebo/Red</material>

    <sensor name="laser" type="ray">
      <pose> 0 0 0 0 0 0 </pose>
      <visualize>true</visualize>
      <update_rate>10</update_rate>
      <ray>
        <scan>
          <horizontal>
            <samples>360</samples>
            <min_angle>-3.14</min_angle>
            <max_angle>3.14</max_angle>
          </horizontal>
        </scan>
        <range>
          <min>0.3</min>
          <max>12</max>
        </range>
      </ray>
      <plugin name="laser_controller" filename="libgazebo_ros_ray_sensor.so">
        <ros>
          <argument>~/out:=scan</argument>
        </ros>
        <output_type>sensor_msgs/LaserScan</output_type>
        <frame_name>laser_frame</frame_name>
      </plugin>
    </sensor>
  </gazebo>

  <gazebo reference="base_link">
    <gravity>true</gravity>
    <sensor name="imu_sensor" type="imu">
      <always_on>true</always_on>
      <update_rate>100</update_rate>
      <visualize>true</visualize>
      <topic>__default_topic__</topic>
      <plugin filename="libgazebo_ros_imu_sensor.so" name="imu_plugin">
        <topicName>imu</topicName>
        <bodyName>base_link</bodyName>
        <updateRateHZ>10.0</updateRateHZ>
        <gaussianNoise>0.0</gaussianNoise>
        <xyzOffset>0 0 0</xyzOffset>
        <rpyOffset>0 0 0</rpyOffset>
        <frameName>base_link</frameName>
        <initialOrientationAsReference>false</initialOrientationAsReference>
      </plugin>
      <pose>0 0 0 0 0 0</pose>
    </sensor>
  </gazebo>
</robot>